<?xml version="1.0" encoding="UTF-8"?>
<testng-results skipped="0" failed="3" ignored="0" total="3" passed="0">
  <reporter-output>
  </reporter-output>
  <suite name="Default suite" duration-ms="35975" started-at="2017-03-15T11:08:47Z" finished-at="2017-03-15T11:09:23Z">
    <groups>
    </groups>
    <test name="Default test" duration-ms="35975" started-at="2017-03-15T11:08:47Z" finished-at="2017-03-15T11:09:23Z">
      <class name="com.indeed.tests.DataDrivenTesting">
        <test-method status="PASS" signature="setup()[pri:0, instance:com.indeed.tests.DataDrivenTesting@735b5592]" name="setup" is-config="true" duration-ms="12734" started-at="2017-03-15T16:38:48Z" finished-at="2017-03-15T16:39:01Z">
          <reporter-output>
          </reporter-output>
        </test-method> <!-- setup -->
        <test-method status="FAIL" signature="doLogin(java.lang.String, java.lang.String)[pri:0, instance:com.indeed.tests.DataDrivenTesting@735b5592]" name="doLogin" duration-ms="2260" started-at="2017-03-15T16:39:01Z" data-provider="getData" finished-at="2017-03-15T16:39:03Z">
          <params>
            <param index="0">
              <value>
                <![CDATA[user1]]>
              </value>
            </param>
            <param index="1">
              <value>
                <![CDATA[pass1]]>
              </value>
            </param>
          </params>
          <exception class="java.lang.AssertionError">
            <message>
              <![CDATA[user unable to login expected [true] but found [false]]]>
            </message>
            <full-stacktrace>
              <![CDATA[java.lang.AssertionError: user unable to login expected [true] but found [false]
	at org.testng.Assert.fail(Assert.java:93)
	at org.testng.Assert.failNotEquals(Assert.java:512)
	at org.testng.Assert.assertTrue(Assert.java:41)
	at com.indeed.tests.DataDrivenTesting.doLogin(DataDrivenTesting.java:40)
	at sun.reflect.NativeMethodAccessorImpl.invoke0(Native Method)
	at sun.reflect.NativeMethodAccessorImpl.invoke(Unknown Source)
	at sun.reflect.DelegatingMethodAccessorImpl.invoke(Unknown Source)
	at java.lang.reflect.Method.invoke(Unknown Source)
	at org.testng.internal.MethodInvocationHelper.invokeMethod(MethodInvocationHelper.java:108)
	at org.testng.internal.Invoker.invokeMethod(Invoker.java:661)
	at org.testng.internal.Invoker.invokeTestMethod(Invoker.java:869)
	at org.testng.internal.Invoker.invokeTestMethods(Invoker.java:1193)
	at org.testng.internal.TestMethodWorker.invokeTestMethods(TestMethodWorker.java:126)
	at org.testng.internal.TestMethodWorker.run(TestMethodWorker.java:109)
	at org.testng.TestRunner.privateRun(TestRunner.java:744)
	at org.testng.TestRunner.run(TestRunner.java:602)
	at org.testng.SuiteRunner.runTest(SuiteRunner.java:380)
	at org.testng.SuiteRunner.runSequentially(SuiteRunner.java:375)
	at org.testng.SuiteRunner.privateRun(SuiteRunner.java:340)
	at org.testng.SuiteRunner.run(SuiteRunner.java:289)
	at org.testng.SuiteRunnerWorker.runSuite(SuiteRunnerWorker.java:52)
	at org.testng.SuiteRunnerWorker.run(SuiteRunnerWorker.java:86)
	at org.testng.TestNG.runSuitesSequentially(TestNG.java:1301)
	at org.testng.TestNG.runSuitesLocally(TestNG.java:1226)
	at org.testng.TestNG.runSuites(TestNG.java:1144)
	at org.testng.TestNG.run(TestNG.java:1115)
	at org.testng.remote.AbstractRemoteTestNG.run(AbstractRemoteTestNG.java:132)
	at org.testng.remote.RemoteTestNG.initAndRun(RemoteTestNG.java:230)
	at org.testng.remote.RemoteTestNG.main(RemoteTestNG.java:76)
]]>
            </full-stacktrace>
          </exception> <!-- java.lang.AssertionError -->
          <reporter-output>
          </reporter-output>
        </test-method> <!-- doLogin -->
        <test-method status="PASS" signature="QuitTC()[pri:0, instance:com.indeed.tests.DataDrivenTesting@735b5592]" name="QuitTC" is-config="true" duration-ms="1563" started-at="2017-03-15T16:39:03Z" finished-at="2017-03-15T16:39:05Z">
          <reporter-output>
          </reporter-output>
        </test-method> <!-- QuitTC -->
        <test-method status="PASS" signature="setup()[pri:0, instance:com.indeed.tests.DataDrivenTesting@735b5592]" name="setup" is-config="true" duration-ms="6832" started-at="2017-03-15T16:39:05Z" finished-at="2017-03-15T16:39:12Z">
          <reporter-output>
          </reporter-output>
        </test-method> <!-- setup -->
        <test-method status="FAIL" signature="doLogin(java.lang.String, java.lang.String)[pri:0, instance:com.indeed.tests.DataDrivenTesting@735b5592]" name="doLogin" duration-ms="1202" started-at="2017-03-15T16:39:12Z" data-provider="getData" finished-at="2017-03-15T16:39:13Z">
          <params>
            <param index="0">
              <value>
                <![CDATA[admin]]>
              </value>
            </param>
            <param index="1">
              <value>
                <![CDATA[demo123]]>
              </value>
            </param>
          </params>
          <exception class="java.lang.AssertionError">
            <message>
              <![CDATA[user unable to login expected [true] but found [false]]]>
            </message>
            <full-stacktrace>
              <![CDATA[java.lang.AssertionError: user unable to login expected [true] but found [false]
	at org.testng.Assert.fail(Assert.java:93)
	at org.testng.Assert.failNotEquals(Assert.java:512)
	at org.testng.Assert.assertTrue(Assert.java:41)
	at com.indeed.tests.DataDrivenTesting.doLogin(DataDrivenTesting.java:40)
	at sun.reflect.NativeMethodAccessorImpl.invoke0(Native Method)
	at sun.reflect.NativeMethodAccessorImpl.invoke(Unknown Source)
	at sun.reflect.DelegatingMethodAccessorImpl.invoke(Unknown Source)
	at java.lang.reflect.Method.invoke(Unknown Source)
	at org.testng.internal.MethodInvocationHelper.invokeMethod(MethodInvocationHelper.java:108)
	at org.testng.internal.Invoker.invokeMethod(Invoker.java:661)
	at org.testng.internal.Invoker.invokeTestMethod(Invoker.java:869)
	at org.testng.internal.Invoker.invokeTestMethods(Invoker.java:1193)
	at org.testng.internal.TestMethodWorker.invokeTestMethods(TestMethodWorker.java:126)
	at org.testng.internal.TestMethodWorker.run(TestMethodWorker.java:109)
	at org.testng.TestRunner.privateRun(TestRunner.java:744)
	at org.testng.TestRunner.run(TestRunner.java:602)
	at org.testng.SuiteRunner.runTest(SuiteRunner.java:380)
	at org.testng.SuiteRunner.runSequentially(SuiteRunner.java:375)
	at org.testng.SuiteRunner.privateRun(SuiteRunner.java:340)
	at org.testng.SuiteRunner.run(SuiteRunner.java:289)
	at org.testng.SuiteRunnerWorker.runSuite(SuiteRunnerWorker.java:52)
	at org.testng.SuiteRunnerWorker.run(SuiteRunnerWorker.java:86)
	at org.testng.TestNG.runSuitesSequentially(TestNG.java:1301)
	at org.testng.TestNG.runSuitesLocally(TestNG.java:1226)
	at org.testng.TestNG.runSuites(TestNG.java:1144)
	at org.testng.TestNG.run(TestNG.java:1115)
	at org.testng.remote.AbstractRemoteTestNG.run(AbstractRemoteTestNG.java:132)
	at org.testng.remote.RemoteTestNG.initAndRun(RemoteTestNG.java:230)
	at org.testng.remote.RemoteTestNG.main(RemoteTestNG.java:76)
]]>
            </full-stacktrace>
          </exception> <!-- java.lang.AssertionError -->
          <reporter-output>
          </reporter-output>
        </test-method> <!-- doLogin -->
        <test-method status="PASS" signature="QuitTC()[pri:0, instance:com.indeed.tests.DataDrivenTesting@735b5592]" name="QuitTC" is-config="true" duration-ms="967" started-at="2017-03-15T16:39:13Z" finished-at="2017-03-15T16:39:14Z">
          <reporter-output>
          </reporter-output>
        </test-method> <!-- QuitTC -->
        <test-method status="PASS" signature="setup()[pri:0, instance:com.indeed.tests.DataDrivenTesting@735b5592]" name="setup" is-config="true" duration-ms="6311" started-at="2017-03-15T16:39:14Z" finished-at="2017-03-15T16:39:20Z">
          <reporter-output>
          </reporter-output>
        </test-method> <!-- setup -->
        <test-method status="FAIL" signature="doLogin(java.lang.String, java.lang.String)[pri:0, instance:com.indeed.tests.DataDrivenTesting@735b5592]" name="doLogin" duration-ms="2198" started-at="2017-03-15T16:39:20Z" data-provider="getData" finished-at="2017-03-15T16:39:22Z">
          <params>
            <param index="0">
              <value>
                <![CDATA[user3]]>
              </value>
            </param>
            <param index="1">
              <value>
                <![CDATA[pass3]]>
              </value>
            </param>
          </params>
          <exception class="java.lang.AssertionError">
            <message>
              <![CDATA[user unable to login expected [true] but found [false]]]>
            </message>
            <full-stacktrace>
              <![CDATA[java.lang.AssertionError: user unable to login expected [true] but found [false]
	at org.testng.Assert.fail(Assert.java:93)
	at org.testng.Assert.failNotEquals(Assert.java:512)
	at org.testng.Assert.assertTrue(Assert.java:41)
	at com.indeed.tests.DataDrivenTesting.doLogin(DataDrivenTesting.java:40)
	at sun.reflect.NativeMethodAccessorImpl.invoke0(Native Method)
	at sun.reflect.NativeMethodAccessorImpl.invoke(Unknown Source)
	at sun.reflect.DelegatingMethodAccessorImpl.invoke(Unknown Source)
	at java.lang.reflect.Method.invoke(Unknown Source)
	at org.testng.internal.MethodInvocationHelper.invokeMethod(MethodInvocationHelper.java:108)
	at org.testng.internal.Invoker.invokeMethod(Invoker.java:661)
	at org.testng.internal.Invoker.invokeTestMethod(Invoker.java:869)
	at org.testng.internal.Invoker.invokeTestMethods(Invoker.java:1193)
	at org.testng.internal.TestMethodWorker.invokeTestMethods(TestMethodWorker.java:126)
	at org.testng.internal.TestMethodWorker.run(TestMethodWorker.java:109)
	at org.testng.TestRunner.privateRun(TestRunner.java:744)
	at org.testng.TestRunner.run(TestRunner.java:602)
	at org.testng.SuiteRunner.runTest(SuiteRunner.java:380)
	at org.testng.SuiteRunner.runSequentially(SuiteRunner.java:375)
	at org.testng.SuiteRunner.privateRun(SuiteRunner.java:340)
	at org.testng.SuiteRunner.run(SuiteRunner.java:289)
	at org.testng.SuiteRunnerWorker.runSuite(SuiteRunnerWorker.java:52)
	at org.testng.SuiteRunnerWorker.run(SuiteRunnerWorker.java:86)
	at org.testng.TestNG.runSuitesSequentially(TestNG.java:1301)
	at org.testng.TestNG.runSuitesLocally(TestNG.java:1226)
	at org.testng.TestNG.runSuites(TestNG.java:1144)
	at org.testng.TestNG.run(TestNG.java:1115)
	at org.testng.remote.AbstractRemoteTestNG.run(AbstractRemoteTestNG.java:132)
	at org.testng.remote.RemoteTestNG.initAndRun(RemoteTestNG.java:230)
	at org.testng.remote.RemoteTestNG.main(RemoteTestNG.java:76)
]]>
            </full-stacktrace>
          </exception> <!-- java.lang.AssertionError -->
          <reporter-output>
          </reporter-output>
        </test-method> <!-- doLogin -->
        <test-method status="PASS" signature="QuitTC()[pri:0, instance:com.indeed.tests.DataDrivenTesting@735b5592]" name="QuitTC" is-config="true" duration-ms="910" started-at="2017-03-15T16:39:22Z" finished-at="2017-03-15T16:39:23Z">
          <reporter-output>
          </reporter-output>
        </test-method> <!-- QuitTC -->
      </class> <!-- com.indeed.tests.DataDrivenTesting -->
    </test> <!-- Default test -->
  </suite> <!-- Default suite -->
</testng-results>
